Workbook

Sheet multiple health
A1: multiple_mental_complaints | B1: (Multiple Items)
A3: Count of seqno_int | C3: multiple_health_complaints
A4: age_recoded | B4: sex_recoded | C4: 0 | D4: 1 | E4: Grand Total
A5: 11 | B5: female | C5: 1151 | D5: 532 | E5: 1683 | G5: =D5/E5 -> 0.3161022
B6: male | C6: 1297 | D6: 371 | E6: 1668 | G6: =D6/E6 -> 0.22242206
A7: 11 Total | C7: 2448 | D7: 903 | E7: 3351 | G7: =D7/E7 -> 0.2694718
A8: 13 | B8: female | C8: 1392 | D8: 1026 | E8: 2418 | G8: =D8/E8 -> 0.42431762
B9: male | C9: 1691 | D9: 543 | E9: 2234 | G9: =D9/E9 -> 0.24306177
A10: 13 Total | C10: 3083 | D10: 1569 | E10: 4652 | G10: =D10/E10 -> 0.33727429
A11: 15 | B11: female | C11: 958 | D11: 1193 | E11: 2151 | G11: =D11/E11 -> 0.55462576
B12: male | C12: 1434 | D12: 568 | E12: 2002 | G12: =D12/E12 -> 0.28371628
A13: 15 Total | C13: 2392 | D13: 1761 | E13: 4153 | G13: =D13/E13 -> 0.42403082
A14: Grand Total | C14: 7923 | D14: 4233 | E14: 12156 | G14: =D14/E14 -> 0.3482231

Sheet mental
A1: multiple_health_complaints | B1: (Multiple Items)
A3: Count of seqno_int | C3: multiple_mental_complaints
A4: age_recoded | B4: sex_recoded | C4: 0 | D4: 1 | E4: Grand Total | G4: mental | H4: multi
A5: 11 | B5: female | C5: 1299 | D5: 384 | E5: 1683 | G5: =D5/E5 -> 0.22816399 | H5: ='multiple health'!G5 -> 0.3161022 | I5: =G5-H5 -> -0.087938206
B6: male | C6: 1420 | D6: 248 | E6: 1668 | G6: =D6/E6 -> 0.14868106 | H6: ='multiple health'!G6 -> 0.22242206 | I6: =G6-H6 -> -0.073741007
A7: 11 Total | C7: 2719 | D7: 632 | E7: 3351 | G7: =D7/E7 -> 0.18860042 | H7: ='multiple health'!G7 -> 0.2694718 | I7: =G7-H7 -> -0.080871382
A8: 13 | B8: female | C8: 1618 | D8: 800 | E8: 2418 | G8: =D8/E8 -> 0.33085194 | H8: ='multiple health'!G8 -> 0.42431762 | I8: =G8-H8 -> -0.093465674
B9: male | C9: 1843 | D9: 391 | E9: 2234 | G9: =D9/E9 -> 0.17502238 | H9: ='multiple health'!G9 -> 0.24306177 | I9: =G9-H9 -> -0.068039391
A10: 13 Total | C10: 3461 | D10: 1191 | E10: 4652 | G10: =D10/E10 -> 0.25601892 | H10: ='multiple health'!G10 -> 0.33727429 | I10: =G10-H10 -> -0.081255374
A11: 15 | B11: female | C11: 1226 | D11: 925 | E11: 2151 | G11: =D11/E11 -> 0.43003254 | H11: ='multiple health'!G11 -> 0.55462576 | I11: =G11-H11 -> -0.12459321
B12: male | C12: 1601 | D12: 401 | E12: 2002 | G12: =D12/E12 -> 0.2002997 | H12: ='multiple health'!G12 -> 0.28371628 | I12: =G12-H12 -> -0.083416583
A13: 15 Total | C13: 2827 | D13: 1326 | E13: 4153 | G13: =D13/E13 -> 0.31928726 | H13: ='multiple health'!G13 -> 0.42403082 | I13: =G13-H13 -> -0.10474356
A14: Grand Total | C14: 9007 | D14: 3149 | E14: 12156 | G14: =D14/E14 -> 0.25904903 | H14: ='multiple health'!G14 -> 0.3482231 | I14: =G14-H14 -> -0.08917407

Sheet canada
A1: seqno_int | B1: agecat | C1: sex | D1: lifesat | E1: headache | F1: stomachache | G1: backache | H1: dizzy | I1: feellow | J1: irritable | K1: nervous | L1: sleepdificulty | M1: lifesat_low | N1: headache_frequent | O1: stomachache_frequent | P1: backache_frequent | Q1: dizzy_frequent | R1: feellow_frequent | S1: irritable_frequent | T1: nervous_frequent | U1: sleepdificulty_frequent | V1: mental_complaints_sum | W1: physical_complaints_sum | X1: multiple_mental_complaints | Y1: multiple_health_complaints | Z1: age_recoded | AA1: sex_recoded
A2: 800002 | B2: NA | C2: 1 | D2: 9 | E2: 5 | F2: 5 | G2: 5 | H2: 5 | I2: 5 | J2: 5 | K2: 5 | L2: 5 | M2: 0 | N2: 0 | O2: 0 | P2: 0 | Q2: 0 | R2: 0 | S2: 0 | T2: 0 | U2: 0 | V2: 0 | W2: 0 | X2: 0 | Y2: 0 | Z2: NA | AA2: male
A3: 800008 | B3: NA | C3: 1 | D3: 6 | E3: NA | F3: NA | G3: NA | H3: 3 | I3: NA | J3: NA | K3: NA | L3: NA | M3: 0 | N3: NA | O3: NA | P3: NA | Q3: 0 | R3: NA | S3: NA | T3: NA | U3: NA | V3: NA | W3: NA | X3: NA | Y3: NA | Z3: NA | AA3: male
A4: 800015 | B4: NA | C4: 1 | D4: 8 | E4: 5 | F4: 4 | G4: 4 | H4: 5 | I4: 5 | J4: 3 | K4: 4 | L4: 2 | M4: 0 | N4: 0 | O4: 0 | P4: 0 | Q4: 0 | R4: 0 | S4: 0 | T4: 0 | U4: 1 | V4: 1 | W4: 0 | X4: 0 | Y4: 0 | Z4: NA | AA4: male
A5: 800020 | B5: NA | C5: 1 | D5: 7 | E5: 4 | F5: 4 | G5: 5 | H5: 5 | I5: 5 | J5: 4 | K5: 4 | L5: 5 | M5: 0 | N5: 0 | O5: 0 | P5: 0 | Q5: 0 | R5: 0 | S5: 0 | T5: 0 | U5: 0 | V5: 0 | W5: 0 | X5: 0 | Y5: 0 | Z5: NA | AA5: male
A6: 800024 | B6: NA | C6: 1 | D6: 8 | E6: 2 | F6: 4 | G6: 4 | H6: 5 | I6: 5 | J6: 4 | K6: 3 | L6: 2 | M6: 0 | N6: 1 | O6: 0 | P6: 0 | Q6: 0 | R6: 0 | S6: 0 | T6: 0 | U6: 1 | V6: 1 | W6: 1 | X6: 0 | Y6: 1 | Z6: NA | AA6: male
A7: 800026 | B7: NA | C7: 1 | D7: 5 | E7: 4 | F7: 4 | G7: 4 | H7: 5 | I7: 5 | J7: 5 | K7: 5 | L7: 5 | M7: 1 | N7: 0 | O7: 0 | P7: 0 | Q7: 0 | R7: 0 | S7: 0 | T7: 0 | U7: 0 | V7: 0 | W7: 0 | X7: 0 | Y7: 0 | Z7: NA | AA7: male
A8: 800032 | B8: NA | C8: 1 | D8: 9 | E8: 5 | F8: 4 | G8: 5 | H8: 5 | I8: 5 | J8: 5 | K8: 3 | L8: 5 | M8: 0 | N8: 0 | O8: 0 | P8: 0 | Q8: 0 | R8: 0 | S8: 0 | T8: 0 | U8: 0 | V8: 0 | W8: 0 | X8: 0 | Y8: 0 | Z8: NA | AA8: male
A9: 800038 | B9: NA | C9: 1 | D9: 6 | E9: 5 | F9: 4 | G9: 5 | H9: 4 | I9: 5 | J9: 5 | K9: 3 | L9: 5 | M9: 0 | N9: 0 | O9: 0 | P9: 0 | Q9: 0 | R9: 0 | S9: 0 | T9: 0 | U9: 0 | V9: 0 | W9: 0 | X9: 0 | Y9: 0 | Z9: NA | AA9: male
A10: 800043 | B10: NA | C10: 1 | D10: 8 | E10: 5 | F10: 5 | G10: 5 | H10: 5 | I10: 5 | J10: 2 | K10: 4 | L10: 5 | M10: 0 | N10: 0 | O10: 0 | P10: 0 | Q10: 0 | R10: 0 | S10: 1 | T10: 0 | U10: 0 | V10: 1 | W10: 0 | X10: 0 | Y10: 0 | Z10: NA | AA10: male
A11: 800044 | B11: NA | C11: 1 | D11: 9 | E11: NA | F11: NA | G11: NA | H11: NA | I11: NA | J11: NA | K11: NA | L11: NA | M11: 0 | N11: NA | O11: NA | P11: NA | Q11: NA | R11: NA | S11: NA | T11: NA | U11: NA | V11: NA | W11: NA | X11: NA | Y11: NA | Z11: NA | AA11: male
A12: 800045 | B12: NA | C12: 1 | D12: NA | E12: 5 | F12: 5 | G12: 5 | H12: 5 | I12: 5 | J12: 5 | K12: 5 | L12: 5 | M12: NA | N12: 0 | O12: 0 | P12: 0 | Q12: 0 | R12: 0 | S12: 0 | T12: 0 | U12: 0 | V12: 0 | W12: 0 | X12: 0 | Y12: 0 | Z12: NA | AA12: male
A13: 800047 | B13: NA | C13: 1 | D13: 7 | E13: 5 | F13: 5 | G13: 5 | H13: 5 | I13: 5 | J13: 3 | K13: 5 | L13: 5 | M13: 0 | N13: 0 | O13: 0 | P13: 0 | Q13: 0 | R13: 0 | S13: 0 | T13: 0 | U13: 0 | V13: 0 | W13: 0 | X13: 0 | Y13: 0 | Z13: NA | AA13: male
A14: 800050 | B14: NA | C14: 1 | D14: 5 | E14: 3 | F14: 5 | G14: 5 | H14: 5 | I14: 1 | J14: 1 | K14: 2 | L14: 2 | M14: 1 | N14: 0 | O14: 0 | P14: 0 | Q14: 0 | R14: 1 | S14: 1 | T14: 1 | U14: 1 | V14: 4 | W14: 0 | X14: 1 | Y14: 1 | Z14: NA | AA14: male
A15: 800052 | B15: NA | C15: 1 | D15: 9 | E15: 4 | F15: 5 | G15: 5 | H15: 5 | I15: 5 | J15: 5 | K15: 3 | L15: 5 | M15: 0 | N15: 0 | O15: 0 | P15: 0 | Q15: 0 | R15: 0 | S15: 0 | T15: 0 | U15: 0 | V15: 0 | W15: 0 | X15: 0 | Y15: 0 | Z15: NA | AA15: male
A16: 800053 | B16: NA | C16: 1 | D16: 9 | E16: 5 | F16: 4 | G16: 3 | H16: 4 | I16: 2 | J16: 4 | K16: 3 | L16: 4 | M16: 0 | N16: 0 | O16: 0 | P16: 0 | Q16: 0 | R16: 1 | S16: 0 | T16: 0 | U16: 0 | V16: 1 | W16: 0 | X16: 0 | Y16: 0 | Z16: NA | AA16: male
A17: 800071 | B17: NA | C17: 1 | D17: 5 | E17: 5 | F17: NA | G17: 5 | H17: 5 | I17: NA | J17: NA | K17: 4 | L17: 5 | M17: 1 | N17: 0 | O17: NA | P17: 0 | Q17: 0 | R17: NA | S17: NA | T17: 0 | U17: 0 | V17: NA | W17: NA | X17: NA | Y17: NA | Z17: NA | AA17: male
A18: 800078 | B18: NA | C18: 1 | D18: 5 | E18: 2 | F18: 2 | G18: 2 | H18: 2 | I18: 2 | J18: 2 | K18: 2 | L18: 2 | M18: 1 | N18: 1 | O18: 1 | P18: 1 | Q18: 1 | R18: 1 | S18: 1 | T18: 1 | U18: 1 | V18: 4 | W18: 4 | X18: 1 | Y18: 1 | Z18: NA | AA18: male
A19: 800081 | B19: NA | C19: 1 | D19: 7 | E19: 3 | F19: 5 | G19: 4 | H19: 5 | I19: 4 | J19: 5 | K19: 5 | L19: 5 | M19: 0 | N19: 0 | O19: 0 | P19: 0 | Q19: 0 | R19: 0 | S19: 0 | T19: 0 | U19: 0 | V19: 0 | W19: 0 | X19: 0 | Y19: 0 | Z19: NA | AA19: male
A20: 800082 | B20: NA | C20: 1 | D20: 8 | E20: 4 | F20: 5 | G20: 5 | H20: 5 | I20: 5 | J20: 5 | K20: 4 | L20: 5 | M20: 0 | N20: 0 | O20: 0 | P20: 0 | Q20: 0 | R20: 0 | S20: 0 | T20: 0 | U20: 0 | V20: 0 | W20: 0 | X20: 0 | Y20: 0 | Z20: NA | AA20: male
A21: 800085 | B21: NA | C21: 1 | D21: 7 | E21: 5 | F21: 5 | G21: 5 | H21: 5 | I21: 5 | J21: 5 | K21: 5 | L21: 5 | M21: 0 | N21: 0 | O21: 0 | P21: 0 | Q21: 0 | R21: 0 | S21: 0 | T21: 0 | U21: 0 | V21: 0 | W21: 0 | X21: 0 | Y21: 0 | Z21: NA | AA21: male
A22: 800087 | B22: NA | C22: 1 | D22: 10 | E22: 5 | F22: 4 | G22: 5 | H22: 5 | I22: 5 | J22: 5 | K22: 5 | L22: 5 | M22: 0 | N22: 0 | O22: 0 | P22: 0 | Q22: 0 | R22: 0 | S22: 0 | T22: 0 | U22: 0 | V22: 0 | W22: 0 | X22: 0 | Y22: 0 | Z22: NA | AA22: male
A23: 800090 | B23: NA | C23: 1 | D23: 7 | E23: 4 | F23: 3 | G23: 3 | H23: 3 | I23: 3 | J23: 3 | K23: 4 | L23: 3 | M23: 0 | N23: 0 | O23: 0 | P23: 0 | Q23: 0 | R23: 0 | S23: 0 | T23: 0 | U23: 0 | V23: 0 | W23: 0 | X23: 0 | Y23: 0 | Z23: NA | AA23: male
A24: 800091 | B24: NA | C24: 1 | D24: 8 | E24: 5 | F24: 5 | G24: 5 | H24: 5 | I24: 5 | J24: 5 | K24: 5 | L24: 5 | M24: 0 | N24: 0 | O24: 0 | P24: 0 | Q24: 0 | R24: 0 | S24: 0 | T24: 0 | U24: 0 | V24: 0 | W24: 0 | X24: 0 | Y24: 0 | Z24: NA | AA24: male
A25: 800092 | B25: NA | C25: 1 | D25: NA | E25: 5 | F25: 5 | G25: 4 | H25: 4 | I25: 3 | J25: 2 | K25: 5 | L25: 5 | M25: NA | N25: 0 | O25: 0 | P25: 0 | Q25: 0 | R25: 0 | S25: 1 | T25: 0 | U25: 0 | V25: 1 | W25: 0 | X25: 0 | Y25: 0 | Z25: NA | AA25: male
A26: 800094 | B26: NA | C26: 1 | D26: NA | E26: 1 | F26: 5 | G26: 1 | H26: 1 | I26: 5 | J26: 5 | K26: 5 | L26: 1 | M26: NA | N26: 1 | O26: 0 | P26: 1 | Q26: 1 | R26: 0 | S26: 0 | T26: 0 | U26: 1 | V26: 1 | W26: 3 | X26: 0 | Y26: 1 | Z26: NA | AA26: male
A27: 800100 | B27: NA | C27: 1 | D27: 7 | E27: 2 | F27: 3 | G27: 1 | H27: 4 | I27: 5 | J27: 5 | K27: 3 | L27: 4 | M27: 0 | N27: 1 | O27: 0 | P27: 1 | Q27: 0 | R27: 0 | S27: 0 | T27: 0 | U27: 0 | V27: 0 | W27: 2 | X27: 0 | Y27: 1 | Z27: NA | AA27: male
A28: 800103 | B28: NA | C28: 1 | D28: 1 | E28: 3 | F28: 3 | G28: 3 | H28: 3 | I28: 4 | J28: 3 | K28: 2 | L28: 2 | M28: 1 | N28: 0 | O28: 0 | P28: 0 | Q28: 0 | R28: 0 | S28: 0 | T28: 1 | U28: 1 | V28: 2 | W28: 0 | X28: 1 | Y28: 1 | Z28: NA | AA28: male
A29: 800105 | B29: NA | C29: 1 | D29: 8 | E29: 5 | F29: 5 | G29: 4 | H29: 5 | I29: 5 | J29: 4 | K29: 4 | L29: 3 | M29: 0 | N29: 0 | O29: 0 | P29: 0 | Q29: 0 | R29: 0 | S29: 0 | T29: 0 | U29: 0 | V29: 0 | W29: 0 | X29: 0 | Y29: 0 | Z29: NA | AA29: male
A30: 800106 | B30: NA | C30: 1 | D30: 4 | E30: 5 | F30: 4 | G30: 5 | H30: 5 | I30: 3 | J30: 1 | K30: 2 | L30: 2 | M30: 1 | N30: 0 | O30: 0 | P30: 0 | Q30: 0 | R30: 0 | S30: 1 | T30: 1 | U30: 1 | V30: 3 | W30: 0 | X30: 1 | Y30: 1 | Z30: NA | AA30: male
A31: 800112 | B31: NA | C31: 1 | D31: NA | E31: NA | F31: NA | G31: NA | H31: NA | I31: NA | J31: NA | K31: NA | L31: NA | M31: NA | N31: NA | O31: NA | P31: NA | Q31: NA | R31: NA | S31: NA | T31: NA | U31: NA | V31: NA | W31: NA | X31: NA | Y31: NA | Z31: NA | AA31: male
A32: 800113 | B32: NA | C32: 1 | D32: 9 | E32: 4 | F32: 5 | G32: 5 | H32: 5 | I32: 5 | J32: 4 | K32: 3 | L32: 5 | M32: 0 | N32: 0 | O32: 0 | P32: 0 | Q32: 0 | R32: 0 | S32: 0 | T32: 0 | U32: 0 | V32: 0 | W32: 0 | X32: 0 | Y32: 0 | Z32: NA | AA32: male
A33: 800114 | B33: NA | C33: 1 | D33: 7 | E33: 4 | F33: 4 | G33: 5 | H33: 5 | I33: 5 | J33: 3 | K33: 5 | L33: 4 | M33: 0 | N33: 0 | O33: 0 | P33: 0 | Q33: 0 | R33: 0 | S33: 0 | T33: 0 | U33: 0 | V33: 0 | W33: 0 | X33: 0 | Y33: 0 | Z33: NA | AA33: male
A34: 800117 | B34: NA | C34: 1 | D34: 9 | E34: 4 | F34: 3 | G34: 5 | H34: 5 | I34: 4 | J34: 5 | K34: 3 | L34: 5 | M34: 0 | N34: 0 | O34: 0 | P34: 0 | Q34: 0 | R34: 0 | S34: 0 | T34: 0 | U34: 0 | V34: 0 | W34: 0 | X34: 0 | Y34: 0 | Z34: NA | AA34: male
A35: 800118 | B35: NA | C35: 1 | D35: 5 | E35: 5 | F35: 3 | G35: 4 | H35: 5 | I35: 2 | J35: 2 | K35: 5 | L35: 3 | M35: 1 | N35: 0 | O35: 0 | P35: 0 | Q35: 0 | R35: 1 | S35: 1 | T35: 0 | U35: 0 | V35: 2 | W35: 0 | X35: 1 | Y35: 1 | Z35: NA | AA35: male
A36: 800121 | B36: NA | C36: 1 | D36: 9 | E36: 5 | F36: 4 | G36: 5 | H36: 5 | I36: 5 | J36: 2 | K36: 4 | L36: 4 | M36: 0 | N36: 0 | O36: 0 | P36: 0 | Q36: 0 | R36: 0 | S36: 1 | T36: 0 | U36: 0 | V36: 1 | W36: 0 | X36: 0 | Y36: 0 | Z36: NA | AA36: male
A37: 800122 | B37: NA | C37: 1 | D37: 8 | E37: 5 | F37: 5 | G37: 5 | H37: 5 | I37: 5 | J37: 5 | K37: 5 | L37: 5 | M37: 0 | N37: 0 | O37: 0 | P37: 0 | Q37: 0 | R37: 0 | S37: 0 | T37: 0 | U37: 0 | V37: 0 | W37: 0 | X37: 0 | Y37: 0 | Z37: NA | AA37: male
A38: 800124 | B38: NA | C38: 1 | D38: 6 | E38: 5 | F38: 5 | G38: 5 | H38: 5 | I38: 5 | J38: 5 | K38: 5 | L38: 5 | M38: 0 | N38: 0 | O38: 0 | P38: 0 | Q38: 0 | R38: 0 | S38: 0 | T38: 0 | U38: 0 | V38: 0 | W38: 0 | X38: 0 | Y38: 0 | Z38: NA | AA38: male
A39: 800125 | B39: NA | C39: 1 | D39: 9 | E39: NA | F39: NA | G39: NA | H39: NA | I39: NA | J39: NA | K39: NA | L39: NA | M39: 0 | N39: NA | O39: NA | P39: NA | Q39: NA | R39: NA | S39: NA | T39: NA | U39: NA | V39: NA | W39: NA | X39: NA | Y39: NA | Z39: NA | AA39: male
A40: 800127 | B40: NA | C40: 1 | D40: 7 | E40: 5 | F40: 5 | G40: 5 | H40: 5 | I40: 3 | J40: 4 | K40: 4 | L40: 4 | M40: 0 | N40: 0 | O40: 0 | P40: 0 | Q40: 0 | R40: 0 | S40: 0 | T40: 0 | U40: 0 | V40: 0 | W40: 0 | X40: 0 | Y40: 0 | Z40: NA | AA40: male
...
